Workbook

Sheet NC
A1: S.No. | B1: Emp Code | C1: Employee First Name | D1: Employee Last Name | E1: User Name | F1: Email | G1: Password | H1: Palnt | I1: Unit | J1: D.O.J
A2: 1 | B2: N0034 | C2: VIKASH | D2: NEGI | E2: =CONCATENATE(C2,".",D2) -> VIKASH.NEGI | F2: N/A | G2: Marelli123 | H2: Plant-1 | I2: Prod-AMT | J2: 42774
A3: 2 | B3: N0036 | C3: RAJENDRA | D3: KUMAR | E3: =CONCATENATE(C3,".",D3) -> RAJENDRA.KUMAR | F3: N/A | G3: Marelli123 | H3: Plant-1 | I3: Prod-AMT | J3: 42949
A4: 3 | B4: N0076 | C4: PRAVIN | D4: KUMAR | E4: =CONCATENATE(C4,".",D4) -> PRAVIN.KUMAR | F4: N/A | G4: Marelli123 | H4: Plant-1 | I4: Prod-AMT | J4: 43040
A5: 4 | B5: N0085 | C5: MANISH | D5: KUMAR | E5: =CONCATENATE(C5,".",D5) -> MANISH.KUMAR | F5: N/A | G5: Marelli123 | H5: Plant-1 | I5: Prod-AMT | J5: 43045
A6: 5 | B6: N0131 | C6: SANJAY | D6: SHAW | E6: =CONCATENATE(C6,".",D6) -> SANJAY.SHAW | F6: N/A | G6: Marelli123 | H6: Plant-1 | I6: Prod-AMT | J6: 43152
A7: 6 | B7: N0186 | C7: DINESH | D7: KUMAR | E7: =CONCATENATE(C7,".",D7) -> DINESH.KUMAR | F7: N/A | G7: Marelli123 | H7: Plant-1 | I7: Prod-AMT | J7: 43224
A8: 7 | B8: N0201 | C8: RAHUL | D8: VERMA | E8: =CONCATENATE(C8,".",D8) -> RAHUL.VERMA | F8: N/A | G8: Marelli123 | H8: Plant-1 | I8: Prod-AMT | J8: 43252
A9: 8 | B9: N0221 | C9: DHARAMENDER | D9: KUMAR | E9: =CONCATENATE(C9,".",D9) -> DHARAMENDER.KUMAR | F9: N/A | G9: Marelli123 | H9: Plant-1 | I9: Prod-AMT | J9: 43285
A10: 9 | B10: N0229 | C10: PRIYABRATA | D10: PRADHAN | E10: =CONCATENATE(C10,".",D10) -> PRIYABRATA.PRADHAN | F10: N/A | G10: Marelli123 | H10: Plant-1 | I10: Prod-AMT | J10: 43320
A11: 10 | B11: N0267 | C11: ATUL | D11: KUMAR | E11: =CONCATENATE(C11,".",D11) -> ATUL.KUMAR | F11: N/A | G11: Marelli123 | H11: Plant-1 | I11: Prod-AMT | J11: 41717
A12: 11 | B12: N0272 | C12: CHANDRAVIR | D12: SINGH | E12: =CONCATENATE(C12,".",D12) -> CHANDRAVIR.SINGH | F12: N/A | G12: Marelli123 | H12: Plant-1 | I12: Prod-AMT | J12: 42684
A13: 12 | B13: N0278 | C13: BITTOO | D13: KUMAR | E13: =CONCATENATE(C13,".",D13) -> BITTOO.KUMAR | F13: N/A | G13: Marelli123 | H13: Plant-1 | I13: Prod-AMT | J13: 44054
... A96: 95 | B96: N0643 | C96: ANIL | D96: KUMAR | E96: =CONCATENATE(C96,".",D96) -> ANIL.KUMAR | F96: N/A | G96: Marelli123 | H96: Plant-1 | I96: Prod-AMT-CNC | J96: 45994

Sheet Dishu
A1: Sr No | B1: Emp Code | C1: Employee First Name | D1: Employee Last Name | E1: User Name | F1: Mail ID | G1: Password | H1: Plant | I1: Unit | J1: D.O.J
A2: 1 | B2: DS-001 | C2: OMPRAKASH | D2: MAHANTA | E2: =CONCATENATE(C2,".",D2) -> OMPRAKASH.MAHANTA | F2: N/A | G2: Marelli123 | H2: Plant-1 | I2: Prod-AMT | J2: 42446
A3: 2 | B3: DS-009 | C3: DHARAM | D3: PAL | E3: =CONCATENATE(C3,".",D3) -> DHARAM.PAL | F3: N/A | G3: Marelli123 | H3: Plant-1 | I3: Prod-AMT | J3: 42627
A4: 3 | B4: DS-010 | C4: PAWAN | D4: KUMAR | E4: =CONCATENATE(C4,".",D4) -> PAWAN.KUMAR | F4: N/A | G4: Marelli123 | H4: Plant-1 | I4: Prod-AMT | J4: 42639
A5: 4 | B5: DS-015 | C5: INDRAJEET | D5: GANGWAR | E5: =CONCATENATE(C5,".",D5) -> INDRAJEET.GANGWAR | F5: N/A | G5: Marelli123 | H5: Plant-1 | I5: Prod-AMT | J5: 42663
A6: 5 | B6: DS-033 | C6: JITENDRAKUMAR | D6: YADAV | E6: =CONCATENATE(C6,".",D6) -> JITENDRAKUMAR.YADAV | F6: N/A | G6: Marelli123 | H6: Plant-1 | I6: Prod-AMT | J6: 42801
A7: 6 | B7: DS-052 | C7: PANKAJ | D7: KUMAR | E7: =CONCATENATE(C7,".",D7) -> PANKAJ.KUMAR | F7: N/A | G7: Marelli123 | H7: Plant-1 | I7: Prod-AMT | J7: 42683
A8: 7 | B8: DS-054 | C8: DILIP | D8: PAL | E8: =CONCATENATE(C8,".",D8) -> DILIP.PAL | F8: N/A | G8: Marelli123 | H8: Plant-1 | I8: Prod-AMT | J8: 42867
A9: 8 | B9: DS-073 | C9: SIKANDAR | D9: YADAV | E9: =CONCATENATE(C9,".",D9) -> SIKANDAR.YADAV | F9: N/A | G9: Marelli123 | H9: Plant-1 | I9: Prod-AMT | J9: 44095
A10: 9 | B10: DS-074 | C10: VIRENDRA | D10: KUMAR | E10: =CONCATENATE(C10,".",D10) -> VIRENDRA.KUMAR | F10: N/A | G10: Marelli123 | H10: Plant-1 | I10: Prod-AMT | J10: 44103
A11: 10 | B11: DS-078 | C11: ANKIT | D11: SHARMA | E11: =CONCATENATE(C11,".",D11) -> ANKIT.SHARMA | F11: N/A | G11: Marelli123 | H11: Plant-1 | I11: Prod-AMT | J11: 44180
A12: 11 | B12: DS-084 | C12: YADUNATH | D12: KUMAR | E12: =CONCATENATE(C12,".",D12) -> YADUNATH .KUMAR | F12: N/A | G12: Marelli123 | H12: Plant-1 | I12: Prod-AMT | J12: 44215
A13: 12 | B13: DS-089 | C13: PAWAN | D13: KUMAR | E13: =CONCATENATE(C13,".",D13) -> PAWAN.KUMAR | F13: N/A | G13: Marelli123 | H13: Plant-1 | I13: Prod-ECU | J13: 44215
... A74: 73 | B74: DS-386 | C74: LAVKUSHKUMAR | D74: PAL | E74: =CONCATENATE(C74,".",D74) -> LAVKUSHKUMAR.PAL | F74: N/A | G74: Marelli123 | H74: Plant-1 | I74: Prod-AMT-CNC | J74: 45994

Sheet Employee
A1: S.NO. | B1: Employee Code | C1: Employee First Name | D1: Employee Last Name | E1: User Name | F1: Mail ID | G1: Password | H1: Plant | I1: Unit | J1: DOJ
A2: 1 | B2: 654 | C2: Pushpender | D2: Kumar | E2: =CONCATENATE(C2,".",D2) -> Pushpender.Kumar | F2: N/A | G2: Marelli123 | H2: Plant-1 | I2: AMT | J2: 39673
A3: 2 | B3: 657 | C3: Shalu | D3: Shalu | E3: =CONCATENATE(C3,".",D3) -> Shalu.Shalu | F3: N/A | G3: Marelli123 | H3: Plant-1 | I3: AMT | J3: 39692
A4: 3 | B4: 658 | C4: Nisha | D4: Sharma | E4: =CONCATENATE(C4,".",D4) -> Nisha.Sharma | F4: N/A | G4: Marelli123 | H4: Plant-1 | I4: ECU | J4: 39701
A5: 4 | B5: 661 | C5: Devender | D5: Sharma | E5: =CONCATENATE(C5,".",D5) -> Devender.Sharma | F5: N/A | G5: Marelli123 | H5: Plant-1 | I5: ECU | J5: 39731
A6: 5 | B6: 663 | C6: Pyare | D6: Lal | E6: =CONCATENATE(C6,".",D6) -> Pyare.Lal | F6: N/A | G6: Marelli123 | H6: Plant-1 | I6: ECU | J6: 39765
A7: 6 | B7: 664 | C7: Manmohan | D7: Singh | E7: =CONCATENATE(C7,".",D7) -> Manmohan.Singh | F7: N/A | G7: Marelli123 | H7: Plant-1 | I7: ECU | J7: 39766
A8: 7 | B8: 667 | C8: Narender | D8: Kumar | E8: =CONCATENATE(C8,".",D8) -> Narender.Kumar | F8: N/A | G8: Marelli123 | H8: Plant-1 | I8: ECU | J8: 39832
A9: 8 | B9: 668 | C9: Sunny | D9: Gola | E9: =CONCATENATE(C9,".",D9) -> Sunny.Gola | F9: N/A | G9: Marelli123 | H9: Plant-1 | I9: ECU | J9: 39832
A10: 9 | B10: 672 | C10: SwarnPratima | D10: Jena | E10: =CONCATENATE(C10,".",D10) -> SwarnPratima.Jena | F10: N/A | G10: Marelli123 | H10: Plant-1 | I10: ECU | J10: 39833
A11: 10 | B11: 675 | C11: Jyoti | D11: Savroop | E11: =CONCATENATE(C11,".",D11) -> Jyoti.Savroop | F11: N/A | G11: Marelli123 | H11: Plant-1 | I11: ECU | J11: 39874
A12: 11 | B12: 676 | C12: Virender | D12: Singh | E12: =CONCATENATE(C12,".",D12) -> Virender.Singh | F12: N/A | G12: Marelli123 | H12: Plant-1 | I12: ECU | J12: 39892
A13: 12 | B13: 680 | C13: Manvinder | D13: Singh | E13: =CONCATENATE(C13,".",D13) -> Manvinder.Singh | F13: N/A | G13: Marelli123 | H13: Plant-1 | I13: ECU | J13: 40077
... A15: 14 | B15: 684 | C15: Lekhraj | D15: Kumar | E15: =CONCATENATE(C15,".",D15) -> Lekhraj.Kumar | F15: N/A | G15: Marelli123 | H15: Plant-1 | I15: ECU | J15: 40122
A16: =A15+1 -> 15 | B16: 686 | C16: DeepakChandra | D16: Kapri | E16: =CONCATENATE(C16,".",D16) -> DeepakChandra.Kapri | F16: N/A | G16: Marelli123 | H16: Plant-1 | I16: ECU | J16: 40142
A17: 16 | B17: 687 | C17: Kuldeep | D17: Yadav | E17: =CONCATENATE(C17,".",D17) -> Kuldeep.Yadav | F17: N/A | G17: Marelli123 | H17: Plant-1 | I17: ECU | J17: 40164
A18: =A17+1 -> 17 | B18: 688 | C18: Jasvir | D18: Kumar | E18: =CONCATENATE(C18,".",D18) -> Jasvir.Kumar | F18: N/A | G18: Marelli123 | H18: Plant-1 | I18: AMT | J18: 40168
A19: =A18+1 -> 18 | B19: 690 | C19: NeerajKumar | D19: Choudhary | E19: =CONCATENATE(C19,".",D19) -> NeerajKumar.Choudhary | F19: N/A | G19: Marelli123 | H19: Plant-1 | I19: ECU | J19: 40189
A20: 19 | B20: 692 | C20: Anuj | D20: Kumar | E20: =CONCATENATE(C20,".",D20) -> Anuj.Kumar | F20: N/A | G20: Marelli123 | H20: Plant-1 | I20: ECU | J20: 40210
A21: =A20+1 -> 20 | B21: 693 | C21: Joginder | D21: Singh | E21: =CONCATENATE(C21,".",D21) -> Joginder.Singh | F21: N/A | G21: Marelli123 | H21: Plant-1 | I21: ECU | J21: 40210
A22: =A21+1 -> 21 | B22: 695 | C22: Ravinder | D22: Singh | E22: =CONCATENATE(C22,".",D22) -> Ravinder .Singh | F22: N/A | G22: Marelli123 | H22: Plant-1 | I22: AMT | J22: 40255
A23: 22 | B23: 696 | C23: Santosh | D23: Singh | E23: =CONCATENATE(C23,".",D23) -> Santosh.Singh | F23: N/A | G23: Marelli123 | H23: Plant-1 | I23: ECU | J23: 40259
A24: =A23+1 -> 23 | B24: 697 | C24: Manju | D24: Kumar | E24: =CONCATENATE(C24,".",D24) -> Manju.Kumar | F24: N/A | G24: Marelli123 | H24: Plant-1 | I24: ECU | J24: 40261
A25: =A24+1 -> 24 | B25: 698 | C25: Ram | D25: Parkash | E25: =CONCATENATE(C25,".",D25) -> Ram.Parkash | F25: N/A | G25: Marelli123 | H25: Plant-1 | I25: ECU | J25: 40261
A26: 25 | B26: 700 | C26: Sunil | D26: Kumar | E26: =CONCATENATE(C26,".",D26) -> Sunil.Kumar | F26: N/A | G26: Marelli123 | H26: Plant-1 | I26: ECU | J26: 40269
A27: =A26+1 -> 26 | B27: 703 | C27: Pawan | D27: Kumar | E27: =CONCATENATE(C27,".",D27) -> Pawan.Kumar | F27: N/A | G27: Marelli123 | H27: Plant-1 | I27: ECU | J27: 40360
A28: =A27+1 -> 27 | B28: 704 | C28: Balwan | D28: Singh | E28: =CONCATENATE(C28,".",D28) -> Balwan.Singh | F28: N/A | G28: Marelli123 | H28: Plant-1 | I28: ECU | J28: 40360
A29: 28 | B29: 709 | C29: Tejpal | D29: Rohilla | E29: =CONCATENATE(C29,".",D29) -> Tejpal.Rohilla | F29: N/A | G29: Marelli123 | H29: Plant-1 | I29: ECU | J29: 40422
A30: =A29+1 -> 29 | B30: 710 | C30: SunilKumar | D30: Yogi | E30: =CONCATENATE(C30,".",D30) -> SunilKumar.Yogi | F30: N/A | G30: Marelli123 | H30: Plant-1 | I30: ECU | J30: 40434
A31: =A30+1 -> 30 | B31: 711 | C31: JoginderSingh | D31: Dhania | E31: =CONCATENATE(C31,".",D31) -> JoginderSingh.Dhania | F31: N/A | G31: Marelli123 | H31: Plant-1 | I31: AMT | J31: 40434
A32: 31 | B32: 712 | C32: Pramila | D32: Devi | E32: =CONCATENATE(C32,".",D32) -> Pramila.Devi | F32: N/A | G32: Marelli123 | H32: Plant-1 | I32: ECU | J32: 40434
A33: =A32+1 -> 32 | B33: 713 | C33: MohanSingh | D33: Naruka | E33: =CONCATENATE(C33,".",D33) -> MohanSingh.Naruka | F33: N/A | G33: Marelli123 | H33: Plant-1 | I33: ECU | J33: 40434
A34: =A33+1 -> 33 | B34: 714 | C34: Amit | D34: Kumar | E34: =CONCATENATE(C34,".",D34) -> Amit.Kumar | F34: N/A | G34: Marelli123 | H34: Plant-1 | I34: ECU | J34: 40466
A35: 34 | B35: 715 | C35: Jitender | D35: Kumar | E35: =CONCATENATE(C35,".",D35) -> Jitender.Kumar | F35: N/A | G35: Marelli123 | H35: Plant-1 | I35: ECU | J35: 40466
A36: =A35+1 -> 35 | B36: 717 | C36: SandeepKumar | D36: Narwalia | E36: =CONCATENATE(C36,".",D36) -> SandeepKumar.Narwalia | F36: N/A | G36: Marelli123 | H36: Plant-1 | I36: ECU | J36: 40469
A37: =A36+1 -> 36 | B37: 720 | C37: Meenakshi | D37: Jhakhar | E37: =CONCATENATE(C37,".",D37) -> Meenakshi.Jhakhar | F37: N/A | G37: Marelli123 | H37: Plant-1 | I37: ECU | J37: 40700
A38: 37 | B38: 729 | C38: Mohit | D38: Rohilla | E38: =CONCATENATE(C38,".",D38) -> Mohit.Rohilla | F38: N/A | G38: Marelli123 | H38: Plant-1 | I38: AMT | J38: 40913
A39: =A38+1 -> 38 | B39: 734 | C39: Anju | D39: Devi | E39: =CONCATENATE(C39,".",D39) -> Anju.Devi | F39: N/A | G39: Marelli123 | H39: Plant-1 | I39: AMT | J39: 40931
A40: =A39+1 -> 39 | B40: 735 | C40: PawanKumar | D40: Guliya | E40: =CONCATENATE(C40,".",D40) -> PawanKumar.Guliya | F40: N/A | G40: Marelli123 | H40: Plant-1 | I40: AMT | J40: 40940
A41: 40 | B41: 736 | C41: Joginder | D41: Kumar | E41: =CONCATENATE(C41,".",D41) -> Joginder.Kumar | F41: N/A | G41: Marelli123 | H41: Plant-1 | I41: ECU | J41: 40969
...

Sheet D-set
A1: S.NO. | B1: Employee Code | C1: Employee First Name | D1: Employee Last Name | E1: User Name | F1: Mail ID | G1: Password | H1: Plant | I1: Unit | J1: DOJ
A2: =[1]Attendance!A5 -> 1 | B2: =[1]Attendance!B5 -> AP-01 | C2: VIVEK | D2: SAXENA | E2: =CONCATENATE(C2,".",D2) -> VIVEK.SAXENA | F2: N/A | G2: Marelli123 | H2: Plant-1 | I2: AMT | J2: =[1]Attendance!Z5 -> 45737
A3: =[1]Attendance!A6 -> 2 | B3: =[1]Attendance!B6 -> AP-10 | C3: SUSHIL | D3: KUMAR | E3: =CONCATENATE(C3,".",D3) -> SUSHIL.KUMAR | F3: N/A | G3: Marelli123 | H3: Plant-1 | I3: AMT | J3: =[1]Attendance!Z6 -> 45786
A4: =[1]Attendance!A7 -> 3 | B4: =[1]Attendance!B7 -> AP-12 | C4: HARISHANKAR | D4: KUMAR | E4: =CONCATENATE(C4,".",D4) -> HARISHANKAR.KUMAR | F4: N/A | G4: Marelli123 | H4: Plant-1 | I4: AMT | J4: =[1]Attendance!Z7 -> 45797
A5: =[1]Attendance!A8 -> 4 | B5: =[1]Attendance!B8 -> AP-13 | C5: =[1]Attendance!D8 -> NIKHIL | D5: KUMAR | E5: =CONCATENATE(C5,".",D5) -> NIKHIL.KUMAR | F5: N/A | G5: Marelli123 | H5: Plant-1 | I5: AMT | J5: =[1]Attendance!Z8 -> 45797
A6: =[1]Attendance!A9 -> 5 | B6: =[1]Attendance!B9 -> AP-25 | C6: DHANANJAY | D6: YADAV | E6: =CONCATENATE(C6,".",D6) -> DHANANJAY.YADAV | F6: N/A | G6: Marelli123 | H6: Plant-1 | I6: AMT | J6: =[1]Attendance!Z9 -> 45819
A7: =[1]Attendance!A10 -> 6 | B7: =[1]Attendance!B10 -> AP-28 | C7: KULDEEP | D7: KUMAR | E7: =CONCATENATE(C7,".",D7) -> KULDEEP.KUMAR | F7: N/A | G7: Marelli123 | H7: Plant-1 | I7: AMT | J7: =[1]Attendance!Z10 -> 45819
A8: =[1]Attendance!A11 -> 7 | B8: =[1]Attendance!B11 -> AP-29 | C8: MOHDTAUREZ | D8: ALAM | E8: =CONCATENATE(C8,".",D8) -> MOHDTAUREZ.ALAM | F8: N/A | G8: Marelli123 | H8: Plant-1 | I8: AMT | J8: =[1]Attendance!Z11 -> 45824
A9: =[1]Attendance!A12 -> 8 | B9: =[1]Attendance!B12 -> AP-31 | C9: =[1]Attendance!D12 -> GAUTAM | D9: KUMAR | E9: =CONCATENATE(C9,".",D9) -> GAUTAM.KUMAR | F9: N/A | G9: Marelli123 | H9: Plant-1 | I9: AMT | J9: =[1]Attendance!Z12 -> 45824
A10: =[1]Attendance!A13 -> 9 | B10: =[1]Attendance!B13 -> AP-38 | C10: SUMIT | D10: SAINI | E10: =CONCATENATE(C10,".",D10) -> SUMIT.SAINI | F10: N/A | G10: Marelli123 | H10: Plant-1 | I10: AMT | J10: =[1]Attendance!Z13 -> 45824
A11: =[1]Attendance!A14 -> 10 | B11: =[1]Attendance!B14 -> AP-42 | C11: =[1]Attendance!D14 -> JATIN | D11: KUMAR | E11: =CONCATENATE(C11,".",D11) -> JATIN.KUMAR | F11: N/A | G11: Marelli123 | H11: Plant-1 | I11: AMT | J11: =[1]Attendance!Z14 -> 45824
A12: =[1]Attendance!A15 -> 11 | B12: =[1]Attendance!B15 -> AP-43 | C12: =[1]Attendance!D15 -> BHARAT | D12: KUMAR | E12: =CONCATENATE(C12,".",D12) -> BHARAT .KUMAR | F12: N/A | G12: Marelli123 | H12: Plant-1 | I12: AMT | J12: =[1]Attendance!Z15 -> 45824
A13: =[1]Attendance!A16 -> 12 | B13: =[1]Attendance!B16 -> AP-44 | C13: JAI | D13: KUMAR | E13: =CONCATENATE(C13,".",D13) -> JAI.KUMAR | F13: N/A | G13: Marelli123 | H13: Plant-1 | I13: AMT | J13: =[1]Attendance!Z16 -> 45824
A14: =[1]Attendance!A17 -> 13 | B14: =[1]Attendance!B17 -> AP-52 | C14: SONUKUMAR | D14: YADAV | E14: =CONCATENATE(C14,".",D14) -> SONUKUMAR.YADAV | F14: N/A | G14: Marelli123 | H14: Plant-1 | I14: AMT | J14: =[1]Attendance!Z17 -> 45840
A15: =[1]Attendance!A18 -> 14 | B15: =[1]Attendance!B18 -> AP-56 | C15: SUSHILKUMAR | D15: THAKUR | E15: =CONCATENATE(C15,".",D15) -> SUSHILKUMAR.THAKUR | F15: N/A | G15: Marelli123 | H15: Plant-1 | I15: AMT | J15: =[1]Attendance!Z18 -> 45840
A16: =[1]Attendance!A19 -> 15 | B16: =[1]Attendance!B19 -> AP-58 | C16: JITENDRA | D16: PRAJAPATI | E16: =CONCATENATE(C16,".",D16) -> JITENDRA.PRAJAPATI | F16: N/A | G16: Marelli123 | H16: Plant-1 | I16: AMT | J16: =[1]Attendance!Z19 -> 45840
A17: =[1]Attendance!A20 -> 16 | B17: =[1]Attendance!B20 -> AP-59 | C17: GAFAR | D17: ANSARI | E17: =CONCATENATE(C17,".",D17) -> GAFAR.ANSARI | F17: N/A | G17: Marelli123 | H17: Plant-1 | I17: AMT | J17: =[1]Attendance!Z20 -> 45840
A18: =[1]Attendance!A21 -> 17 | B18: =[1]Attendance!B21 -> AP-61 | C18: PURNACHANDRA | D18: PARIDA | E18: =CONCATENATE(C18,".",D18) -> PURNACHANDRA.PARIDA | F18: N/A | G18: Marelli123 | H18: Plant-1 | I18: AMT | J18: =[1]Attendance!Z21 -> 45839
A19: =[1]Attendance!A22 -> 18 | B19: =[1]Attendance!B22 -> AP-64 | C19: MANOJ | D19: KUMAR | E19: =CONCATENATE(C19,".",D19) -> MANOJ.KUMAR | F19: N/A | G19: Marelli123 | H19: Plant-1 | I19: AMT | J19: =[1]Attendance!Z22 -> 45839
A20: =[1]Attendance!A23 -> 19 | B20: =[1]Attendance!B23 -> AP-67 | C20: RAHUL | D20: DUBEY | E20: =CONCATENATE(C20,".",D20) -> RAHUL.DUBEY | F20: N/A | G20: Marelli123 | H20: Plant-1 | I20: AMT | J20: =[1]Attendance!Z23 -> 45848
A21: =[1]Attendance!A24 -> 20 | B21: =[1]Attendance!B24 -> AP-69 | C21: VIKASH | D21: KUMAR | E21: =CONCATENATE(C21,".",D21) -> VIKASH.KUMAR | F21: N/A | G21: Marelli123 | H21: Plant-1 | I21: AMT | J21: =[1]Attendance!Z24 -> 45848
A22: =[1]Attendance!A25 -> 21 | B22: =[1]Attendance!B25 -> AP-70 | C22: RAJAKANT | D22: KUMAR | E22: =CONCATENATE(C22,".",D22) -> RAJAKANT.KUMAR | F22: N/A | G22: Marelli123 | H22: Plant-1 | I22: AMT | J22: =[1]Attendance!Z25 -> 45848
A23: =[1]Attendance!A26 -> 22 | B23: =[1]Attendance!B26 -> AP-71 | C23: SOMENDRA | D23: SINGH | E23: =CONCATENATE(C23,".",D23) -> SOMENDRA.SINGH | F23: N/A | G23: Marelli123 | H23: Plant-1 | I23: AMT | J23: =[1]Attendance!Z26 -> 45848
A24: =[1]Attendance!A27 -> 23 | B24: =[1]Attendance!B27 -> AP-74 | C24: =[1]Attendance!D27 -> ANAND | D24: KUMAR | E24: =CONCATENATE(C24,".",D24) -> ANAND.KUMAR | F24: N/A | G24: Marelli123 | H24: Plant-1 | I24: AMT | J24: =[1]Attendance!Z27 -> 45849
A25: =[1]Attendance!A28 -> 24 | B25: =[1]Attendance!B28 -> AP-78 | C25: =[1]Attendance!D28 -> NITIN | D25: KUMAR | E25: =CONCATENATE(C25,".",D25) -> NITIN.KUMAR | F25: N/A | G25: Marelli123 | H25: Plant-1 | I25: AMT | J25: =[1]Attendance!Z28 -> 45859
A26: =[1]Attendance!A29 -> 25 | B26: =[1]Attendance!B29 -> AP-79 | C26: NEERAJ | D26: KUMAR | E26: =CONCATENATE(C26,".",D26) -> NEERAJ .KUMAR | F26: N/A | G26: Marelli123 | H26: Plant-1 | I26: AMT | J26: =[1]Attendance!Z29 -> 45859
A27: =[1]Attendance!A30 -> 26 | B27: =[1]Attendance!B30 -> AP-80 | C27: =[1]Attendance!D30 -> KUSHAL | D27: KUMAR | E27: =CONCATENATE(C27,".",D27) -> KUSHAL.KUMAR | F27: N/A | G27: Marelli123 | H27: Plant-1 | I27: AMT | J27: =[1]Attendance!Z30 -> 45866
A28: =[1]Attendance!A31 -> 27 | B28: =[1]Attendance!B31 -> AP-81 | C28: VISHAL | D28: VERMA | E28: =CONCATENATE(C28,".",D28) -> VISHAL.VERMA | F28: N/A | G28: Marelli123 | H28: Plant-1 | I28: AMT | J28: =[1]Attendance!Z31 -> 45866
A29: =[1]Attendance!A32 -> 28 | B29: =[1]Attendance!B32 -> AP-83 | C29: HARVINDER | D29: SINGH | E29: =CONCATENATE(C29,".",D29) -> HARVINDER.SINGH | F29: N/A | G29: Marelli123 | H29: Plant-1 | I29: AMT | J29: =[1]Attendance!Z32 -> 45866
A30: =[1]Attendance!A33 -> 29 | B30: =[1]Attendance!B33 -> AP-84 | C30: RAJ | D30: KUMAR | E30: =CONCATENATE(C30,".",D30) -> RAJ.KUMAR | F30: N/A | G30: Marelli123 | H30: Plant-1 | I30: AMT | J30: =[1]Attendance!Z33 -> 45866
A31: =[1]Attendance!A34 -> 30 | B31: =[1]Attendance!B34 -> AP-85 | C31: SIDDHANT | D31: BALIYAN | E31: =CONCATENATE(C31,".",D31) -> SIDDHANT.BALIYAN | F31: N/A | G31: Marelli123 | H31: Plant-1 | I31: AMT | J31: =[1]Attendance!Z34 -> 45866
A32: =[1]Attendance!A35 -> 31 | B32: =[1]Attendance!B35 -> AP-86 | C32: PRAVEEN | D32: KUMAR | E32: =CONCATENATE(C32,".",D32) -> PRAVEEN.KUMAR | F32: N/A | G32: Marelli123 | H32: Plant-1 | I32: AMT | J32: =[1]Attendance!Z35 -> 45866
A33: =[1]Attendance!A36 -> 32 | B33: =[1]Attendance!B36 -> AP-91 | C33: MAYANK | D33: JOON | E33: =CONCATENATE(C33,".",D33) -> MAYANK.JOON | F33: N/A | G33: Marelli123 | H33: Plant-1 | I33: AMT | J33: =[1]Attendance!Z36 -> 45887
A34: =[1]Attendance!A37 -> 33 | B34: =[1]Attendance!B37 -> AP-95 | C34: ARVIND | D34: KUMAR | E34: =CONCATENATE(C34,".",D34) -> ARVIND.KUMAR | F34: N/A | G34: Marelli123 | H34: Plant-1 | I34: AMT | J34: =[1]Attendance!Z37 -> 45887
A35: =[1]Attendance!A38 -> 34 | B35: =[1]Attendance!B38 -> AP-96 | C35: =[1]Attendance!D38 -> YOGENDER | D35: KUMAR | E35: =CONCATENATE(C35,".",D35) -> YOGENDER.KUMAR | F35: N/A | G35: Marelli123 | H35: Plant-1 | I35: AMT | J35: =[1]Attendance!Z38 -> 45887
A36: =[1]Attendance!A39 -> 35 | B36: =[1]Attendance!B39 -> AP-97 | C36: =[1]Attendance!D39 -> NEERAJ | D36: KUMAR | E36: =CONCATENATE(C36,".",D36) -> NEERAJ .KUMAR | F36: N/A | G36: Marelli123 | H36: Plant-1 | I36: AMT | J36: =[1]Attendance!Z39 -> 45887
A37: =[1]Attendance!A40 -> 36 | B37: =[1]Attendance!B40 -> AP-98 | C37: VISHAL | D37: SHARMA | E37: =CONCATENATE(C37,".",D37) -> VISHAL.SHARMA | F37: N/A | G37: Marelli123 | H37: Plant-1 | I37: AMT | J37: =[1]Attendance!Z40 -> 45895
A38: =[1]Attendance!A41 -> 37 | B38: =[1]Attendance!B41 -> AP-99 | C38: VIPIN | D38: KUMAR | E38: =CONCATENATE(C38,".",D38) -> VIPIN.KUMAR | F38: N/A | G38: Marelli123 | H38: Plant-1 | I38: AMT | J38: =[1]Attendance!Z41 -> 45895
A39: =[1]Attendance!A42 -> 38 | B39: =[1]Attendance!B42 -> AP-101 | C39: TEJPAL | D39: MEENA | E39: =CONCATENATE(C39,".",D39) -> TEJPAL.MEENA | F39: N/A | G39: Marelli123 | H39: Plant-1 | I39: AMT | J39: =[1]Attendance!Z42 -> 45895
A40: =[1]Attendance!A43 -> 39 | B40: =[1]Attendance!B43 -> AP-105 | C40: =[1]Attendance!D43 -> KISHAN | D40: KUMAR | E40: =CONCATENATE(C40,".",D40) -> KISHAN.KUMAR | F40: N/A | G40: Marelli123 | H40: Plant-1 | I40: AMT | J40: =[1]Attendance!Z43 -> 45895
...

Sheet Production
A1: Production
A2: S.N. | B2: Emp Code | C2: S.F. ID | D2: Name | E2: Line | F2: Shift
A3: 1 | B3: N0131 | C3: IN7038935 | D3: SANJAY SHAW | E3: Rework | F3: G
A4: 2 | B4: N0221 | C4: IN7038941 | D4: DHARAMENDER | E4: Red line | F4: N/A
A5: 3 | B5: N0279 | C5: IN7038947 | D5: BANTI SHARMA | E5: Yellow | F5: G
A6: 4 | B6: N0299 | C6: IN7038956 | D6: LOKESH KUMAR | E6: ECU Prod
A7: 5 | B7: N0309 | C7: IN7038962 | D7: SUNIL MOURYA | E7: VG | F7: A
A8: 6 | B8: N0313 | C8: IN7038965 | D8: RAMDEV VISHVAKARMA | E8: ECU Prod
A9: 7 | B9: N0328 | C9: IN7038975 | D9: NARENDRA KUMAR | E9: Yellow | F9: A
A10: 8 | B10: N0371 | C10: IN7038987 | D10: BHAGWAT SHARMA | E10: Red line | F10: N/A
A11: 9 | B11: N0377 | C11: IN7038988 | D11: SANDEEP KUMAR | E11: Yellow | F11: A
A12: 10 | B12: N0389 | C12: IN7038992 | D12: GAJENDRA PAL SINGH | E12: Red line | F12: N/A
A13: 11 | B13: N0407 | C13: IN7039002 | D13: VIKAS SAINI | E13: PDI | F13: B
A14: 12 | B14: N0408 | C14: IN7039003 | D14: PRAMOD KUMAR YADAV | E14: Yellow | F14: A
A15: 13 | B15: N0412 | C15: IN7039005 | D15: AJMER | E15: ECU Prod
A16: 14 | B16: N0441 | C16: IN7039015 | D16: YADWESH KUMAR YADAV | E16: Washing | F16: N/A
A17: 15 | B17: N0452 | C17: IN7039021 | D17: RAVI KUMAR | E17: Red line | F17: N/A
A18: 16 | B18: N0470 | C18: IN7039030 | D18: RAVI TIWARI | E18: VG | F18: N/A
A19: 17 | B19: N0473 | C19: IN7039032 | D19: UJJAWAL TALIYAN | E19: TEST BENCH | F19: A
A20: 18 | B20: N0497 | C20: IN7039043 | D20: ASHUTOSH KUMAR PANDEY | E20: ECU Prod
A21: 19 | B21: N0499 | C21: IN7039045 | D21: RAVI KUMAR | E21: Accumulator | F21: G
A22: 20 | B22: N0511 | C22: IN7039055 | D22: SURAJ BAGHEL | E22: vg | F22: N/A
A23: 21 | B23: N0524 | C23: IN7039064 | D23: AMIT YADAV | E23: Red line | F23: B
A24: 22 | B24: N0528 | C24: IN7039156 | D24: DHEERAJ KUMAR | E24: Red line | F24: N/A
A25: 23 | B25: N0529 | C25: IN7039162 | D25: PRATAP KUMAR SAMAL | E25: Red line | F25: A
A26: 24 | B26: N0530 | C26: IN7039056 | D26: VIKASH | E26: Red line | F26: N/A
A27: 25 | B27: N0548 | C27: IN0086453 | D27: KAMAL DEV | E27: Washing | F27: N/A
A28: 26 | B28: N0549 | C28: IN0086454 | D28: VISHAL | E28: VG | F28: N/A
A29: 27 | B29: N0567 | C29: IN0088257 | D29: VIJAY KUMAR VISHVKARMA | E29: Red line | F29: N/A
A30: 28 | B30: N0569 | C30: IN0088644 | D30: KAUSHLENDRA SINGH | E30: Washing | F30: N/A
A31: 29 | B31: N0580 | C31: IN0090222 | D31: VIKASH KUMAR | E31: Red line | F31: A
A32: 30 | B32: N0614 | C32: IN0097350 | D32: ADITYA | E32: ECU Prod
A33: 31 | B33: N0617 | C33: IN7039104 | D33: SUMIT KUMAR | E33: Washing | F33: B
A34: 32 | B34: N0637 | C34: IN0105433 | D34: ASHISH KUMAR CHAUDHARY | E34: Red line | F34: B
A35: 33 | B35: DS-011 | C35: IN7039070 | D35: SHASHIKANT SHARMA | E35: red | F35: N/A
A36: 34 | B36: DS-015 | C36: IN7039071 | D36: INDRAJEET GANGWAR | E36: red | F36: N/A
A37: 35 | B37: DS-074 | C37: IN7039083 | D37: VIRENDRA KUMAR | E37: RED | F37: B
A38: 36 | B38: DS-081 | C38: IN7039086 | D38: SURYADEV SAHOO | E38: ECU
A39: 37 | B39: DS-084 | C39: IN7039087 | D39: YADUNATH | E39: WASHING | F39: B
A40: 38 | B40: DS-094 | C40: IN7039092 | D40: SUNIL YOGI | E40: ECU
...

Sheet Quality
A1: Quality
A2: S.N. | B2: Emp Code | C2: S.F. ID | D2: Name | E2: Line | F2: Shift
A3: 1 | B3: 711 | C3: IN0031800 | D3: Joginder Singh Dhania | E3: ECU Quality | F3: C
A4: 2 | B4: 715 | C4: IN0031883 | D4: Jitender Kumar | E4: ECU Quality | F4: B
A5: 3 | B5: 717 | C5: IN0031966 | D5: Sandeep Kumar Narwalia | E5: ECU Quality | F5: G
A6: 4 | B6: 819 | C6: IN0032068 | D6: Divya Kumar Maurya | E6: Cantamination | F6: B
A7: 5 | B7: 1017 | C7: IN0032197 | D7: Rahul Agarwal | E7: Metrology | F7: B
A8: 6 | B8: 1157 | C8: IN0032249 | D8: Simran Singh | E8: Customer Quality | F8: G
A9: 7 | B9: 1192 | C9: IN0032268 | D9: Vikas Kumar | E9: Customer Quality | F9: G
A10: 8 | B10: N0612 | C10: IN7038954 | D10: AMIT | E10: Metrology | F10: G
A11: 9 | B11: N0634 | C11: IN0105427 | D11: YOGESH KUSHWAHA | E11: Cantamination | F11: G
A12: 10 | B12: DS-160 | C12: IN7039118 | D12: SACHIN YADAV | E12: Cantamination | F12: A

Sheet Maint
A1: Maintenance
A2: S.N. | B2: Emp Code | C2: S.F. ID | D2: Name | E2: Line | F2: Shift
A3: 1 | B3: 850 | C3: IN0032089 | D3: Sonveer Singh | E3: AMT Maint | F3: C
A4: 2 | B4: 863 | C4: IN0032105 | D4: Mohammad Irshad | E4: AMT Maint | F4: A
A5: 3 | B5: 920 | C5: IN0032161 | D5: Naresh Kumar Yadav | E5: AMT Maint | F5: G
A6: 4 | B6: 1016 | C6: IN0032196 | D6: Mohit Kumar | E6: AMT Maint | F6: A
A7: 5 | B7: 1062 | C7: IN0032209 | D7: Manoj Prajapati | E7: ECU Maint | F7: C
A8: 6 | B8: 1255 | C8: IN0032297 | D8: Papuni Behera | E8: ECU Maint | F8: A
A9: 7 | B9: 1285 | C9: IN0032314 | D9: Anil Kumar | E9: ECU Maint | F9: B
A10: 8 | B10: N0291 | C10: IN7038955 | D10: ROHIT KUMAR | E10: AMT Maint | F10: A
A11: 9 | B11: N0395 | C11: IN7038997 | D11: TEJPAL | E11: AMT Maint | F11: B
A12: 10 | B12: N0633 | C12: IN0103028 | D12: DHARMENDRA KUMAR | E12: AMT Maint | F12: C
A13: 11 | B13: DS-201 | C13: IN7039131 | D13: AMAN SHARMA | E13: AMT Maint | F13: B
A14: 12 | B14: DS-249 | C14: IN7039155 | D14: JAIPAL | E14: AMT Maint | F14: C
A15: 13 | B15: DS-376 | C15: IN0103027 | D15: LAVKUSH YADAV | E15: AMT Maint | F15: A

Sheet Utility
A1: Utility
A2: S.N. | B2: Emp Code | C2: S.F. ID | D2: Name | E2: Line | F2: Shift
A3: 1 | B3: N0632 | C3: IN0102717 | D3: SUNIL KUMAR | E3: Utility | F3: G
A4: 2 | B4: 747 | C4: IN0031939 | D4: Rakesh Kumar Yadav | E4: Utility | F4: C
A5: 3 | B5: 749 | C5: IN0031947 | D5: Pawan Kumar Yadav | E5: Utility | F5: G
A6: 4 | B6: 750 | C6: IN0031948 | D6: Om Prakash Yadav | E6: Utility | F6: B
A7: 5 | B7: 751 | C7: IN0031949 | D7: Deepak | E7: Utility | F7: A
A8: 6 | B8: 846 | C8: IN0032087 | D8: Rahul Kundal | E8: Utility | F8: A
A9: 7 | B9: 854 | C9: IN0032098 | D9: Rajeev Kumar Laur | E9: Utility | F9: W.OFF
A10: 8 | B10: 1023 | C10: IN0032202 | D10: Manjeet Gond | E10: Utility | F10: B

Sheet Logistic
A1: Logistic
A2: S.N. | B2: Emp Code | C2: S.F. ID | D2: Name | E2: Line | F2: Shift
A3: 1 | B3: 1156 | C3: IN0032248 | D3: Pintu Nigam | E3: Warehouse | F3: G
A4: 2 | B4: 1371 | C4: IN0032370 | D4: Rishi Kumar | E4: Warehouse | F4: C
A5: 3 | B5: N0267 | C5: IN7038927 | D5: ATUL | E5: Warehouse | F5: B
A6: 4 | B6: N0533 | C6: IN0077547 | D6: RAJENDER | E6: Warehouse | F6: B
A7: 5 | B7: N0597 | C7: IN0090711 | D7: NAVEEN KUMAR | E7: Warehouse | F7: G
A8: 6 | B8: N0623 | C8: IN0100149 | D8: GOVIND SINGH | E8: Warehouse | F8: A
A9: 7 | B9: DS-248 | C9: IN7039154 | D9: MANJEET KUMAR | E9: Warehouse | F9: B
A10: 8 | B10: DS-347 | C10: IN0091344 | D10: SUMIT KUMAR | E10: Warehouse | F10: G
